Workbook

Sheet Format NVM Test Scenarios
A1: Test Case ID | B1: Name | C1: Label | D1: Description | E1: Preconditions | F1: Steps | G1: Expected Result | H1: Test Category | I1: Testing Technique | J1: Functional Area | K1: Spec Reference
A2: TC_FORMAT_NVM_001 | B2: Format with valid Format Index (LBAF 0) | C2: FORMAT_NVM_VALID_LBAF_LOW | D2: Verify Format NVM command succeeds when Format Index points to LBA Format 0 (lower boundary), which is the default supported LBA format from Identify Namespace. | E2: 1. Controller is initialized and admin queue is operational. 2. Target namespace is attached and active. 3. LBA Format 0 is supported as reported in Identify Namespace LBA Format field. 4. No outstanding I/O on namespace. | F2: 1. Issue Identify Namespace (CNS=00h) and read LBAF[0] capabilities. 2. Issue Format NVM with NSID=valid, CDW10.LBAF=0, PI=000b, PIL=0, MSET=0. 3. Wait for command completion. 4. Re-issue Identify Namespace and verify FLBAS field reflects Format Index 0. | G2: Command completes with status Successful Completion (00h). FLBAS field in Identify Namespace indicates LBA Format 0. Namespace is usable. | H2: Positive | I2: Boundary Value Analysis | J2: Format Index validation | K2: Sec 4.1.2; Fig 90 (CDW10)
A3: TC_FORMAT_NVM_002 | B3: Format with valid Format Index (max supported LBAF) | C3: FORMAT_NVM_VALID_LBAF_HIGH | D3: Verify Format NVM command succeeds when Format Index points to the highest LBA Format index supported by the namespace (NLBAF boundary upper). | E3: 1. Controller initialized. 2. Identify Namespace returns NLBAF > 0 indicating multiple supported LBA formats. 3. Namespace attached and idle. | F3: 1. Read NLBAF from Identify Namespace and determine highest supported Format Index N (where N <= NLBAF). 2. Issue Format NVM with CDW10.LBAF=N, PI=000b, PIL=0, MSET as supported. 3. Wait for completion. 4. Re-read FLBAS and confirm change. | G3: Command completes with Successful Completion (00h). FLBAS field reflects Format Index N. LBA size and metadata size match the LBAF[N] entry. | H3: Positive | I3: Boundary Value Analysis | J3: Format Index validation | K3: Sec 4.1.2
A4: TC_FORMAT_NVM_003 | B4: Format with Format Index above max supported LBAF | C4: FORMAT_NVM_INVALID_LBAF_OUT_OF_RANGE | D4: Verify Format NVM command is aborted when Format Index references an LBA Format index greater than NLBAF reported by Identify Namespace. | E4: 1. Controller initialized. 2. Identify Namespace returns NLBAF=N (so valid LBAF indices are 0..N). 3. Namespace attached. | F4: 1. Read NLBAF from Identify Namespace. 2. Issue Format NVM with CDW10.LBAF=(N+1). 3. Observe completion status. | G4: Command aborts with status code Invalid Format (0Ah) or Invalid Field in Command. Namespace LBA Format remains unchanged (verify FLBAS unchanged). | H4: Negative | I4: Boundary Value Analysis | J4: Format Index validation | K4: Sec 4.1.2
A5: TC_FORMAT_NVM_004 | B5: Format with Format Index = 0xF (all-ones nibble) | C5: FORMAT_NVM_INVALID_LBAF_MAX_FIELD | D5: Error guessing: verify behavior when LBAF field is set to its max representable value (0xF or higher per extended bits) on a device that does not support that LBAF. | E5: 1. Identify Namespace shows NLBAF < 0xF. 2. Namespace attached. | F5: 1. Issue Format NVM with CDW10.LBAF=0xF. 2. Observe completion status. | G5: Command aborts with Invalid Format (0Ah) or equivalent error. Namespace remains unchanged. | H5: Negative | I5: Error Guessing | J5: Format Index validation | K5: Sec 4.1.2
A6: TC_FORMAT_NVM_005 | B6: NSZE and NCAP update after change of logical block size | C6: FORMAT_NVM_NSZE_NCAP_CHANGE | D6: Verify that when Format NVM changes the logical block size, the resulting NSZE and NCAP fields in Identify Namespace may differ from the previous values. | E6: 1. Namespace currently formatted with LBA size = 512B (LBAF[0]). 2. LBAF[1] supports 4096B blocks. 3. Capture pre-format NSZE and NCAP. | F6: 1. Read pre-format NSZE and NCAP from Identify Namespace. 2. Issue Format NVM with LBAF=1 (4096B block). 3. Wait for completion. 4. Re-read NSZE, NCAP from Identify Namespace. | G6: Command completes successfully. New NSZE and NCAP reflect the new LBA size (typically 1/8 of previous values for 512B->4096B). Total raw capacity (NSZE * LBA size) is consistent. | H6: Positive | I6: Equivalence Partitioning | J6: Namespace size/capacity behavior | K6: Sec 4.1.2
A7: TC_FORMAT_NVM_006 | B7: NSZE and NCAP unchanged when LBA size is identical | C7: FORMAT_NVM_NSZE_NCAP_NO_CHANGE | D7: Corner case: verify NSZE and NCAP are unchanged when Format NVM is issued with the same LBA Format index as currently configured (no logical block size change). | E7: 1. Namespace formatted with LBAF=K. 2. Capture pre-format NSZE, NCAP. | F7: 1. Read NSZE, NCAP. 2. Issue Format NVM with LBAF=K (same as current). 3. Read NSZE, NCAP again. | G7: Command completes successfully. NSZE and NCAP remain identical to previous values. Namespace data is erased per Format semantics. | H7: Corner | I7: Exploratory | J7: Namespace size/capacity behavior | K7: Sec 4.1.2
A8: TC_FORMAT_NVM_007 | B8: LBAFEE=0, Format with 16b Guard PI and STS=0 | C8: FORMAT_NVM_LBAFEE0_16B_STS0_OK | D8: Verify that Format NVM succeeds with 16b Guard Protection Information when STS=0 even though LBAFEE is not enabled (the spec only restricts STS != 0 in this case). | E8: 1. LBAFEE in Host Behavior Support feature is NOT set to 1h (cleared/0h). 2. Target LBAF supports 16b Guard PI and has STS=0. | F8: 1. Read Host Behavior Support feature; confirm LBAFEE != 1h. 2. Issue Format NVM with LBAF that uses 16b Guard PI and STS=0, PI=001b (Type 1). 3. Wait for completion. | G8: Command completes with Successful Completion. Namespace is formatted with 16b Guard PI. | H8: Positive | I8: Equivalence Partitioning | J8: LBAFEE / extended PI handling | K8: Sec 4.1.2 (LBAFEE rule)
A9: TC_FORMAT_NVM_008 | B9: LBAFEE=0, Format with 16b Guard PI and STS != 0 | C9: FORMAT_NVM_LBAFEE0_16B_STSNZ_FAIL | D9: Verify Format NVM is aborted with Invalid Namespace or Format when LBAFEE != 1h and the requested LBA format uses 16b Guard PI with a non-zero STS field. | E9: 1. LBAFEE NOT set to 1h. 2. Device supports an LBAF with 16b Guard PI where STS field is non-zero. | F9: 1. Verify LBAFEE is not 1h via Get Features. 2. Issue Format NVM specifying that LBAF (16b Guard PI, STS != 0). 3. Observe completion. | G9: Command aborts with status code Invalid Namespace or Format (status code per Base spec). Namespace LBA format remains unchanged. | H9: Negative | I9: Equivalence Partitioning | J9: LBAFEE / extended PI handling | K9: Sec 4.1.2 bullet (a)
A10: TC_FORMAT_NVM_009 | B10: LBAFEE=0, Format with 32b Guard Protection Information | C10: FORMAT_NVM_LBAFEE0_32B_FAIL | D10: Verify Format NVM is aborted with Invalid Namespace or Format when LBAFEE != 1h and requested LBAF uses 32b Guard Protection Information. | E10: 1. LBAFEE NOT set to 1h. 2. Device supports an LBAF that uses 32b Guard PI. | F10: 1. Confirm LBAFEE != 1h. 2. Issue Format NVM specifying the 32b Guard PI LBAF. 3. Observe completion. | G10: Command aborts with status code Invalid Namespace or Format. Namespace remains unchanged. | H10: Negative | I10: Equivalence Partitioning | J10: LBAFEE / extended PI handling | K10: Sec 4.1.2 bullet (b)
A11: TC_FORMAT_NVM_010 | B11: LBAFEE=0, Format with 64b Guard Protection Information | C11: FORMAT_NVM_LBAFEE0_64B_FAIL | D11: Verify Format NVM is aborted with Invalid Namespace or Format when LBAFEE != 1h and requested LBAF uses 64b Guard Protection Information. | E11: 1. LBAFEE NOT set to 1h. 2. Device supports an LBAF using 64b Guard PI. | F11: 1. Confirm LBAFEE != 1h. 2. Issue Format NVM specifying the 64b Guard PI LBAF. 3. Observe completion. | G11: Command aborts with status code Invalid Namespace or Format. Namespace remains unchanged. | H11: Negative | I11: Equivalence Partitioning | J11: LBAFEE / extended PI handling | K11: Sec 4.1.2 bullet (c)
A12: TC_FORMAT_NVM_011 | B12: LBAFEE=0 on namespace already formatted with 32b Guard PI | C12: FORMAT_NVM_LBAFEE0_NS_ALREADY_32B_FAIL | D12: Verify Format NVM is aborted with Invalid Namespace or Format when the target namespace is already formatted with 32b Guard PI and LBAFEE is not 1h, regardless of the new LBAF requested. | E12: 1. Namespace is currently formatted with 32b Guard PI. 2. Host clears LBAFEE to 0h via Set Features (Host Behavior Support). | F12: 1. Verify LBAFEE = 0h. 2. Issue Format NVM (any new LBAF) on this namespace. 3. Observe completion. | G12: Command aborts with status code Invalid Namespace or Format because the affected namespace is currently formatted with 32b Guard PI. | H12: Negative | I12: Error Guessing | J12: LBAFEE / extended PI handling | K12: Sec 4.1.2 ('specifies an individual namespace formatted with')
... A63: TC_FORMAT_NVM_062 | B63: Format with FNA bit 0 set - cryptographic erase on format | C63: FORMAT_NVM_FNA_CRYPTO_ERASE | D63: Verify Format NVM with Secure Erase Setting (SES) field per Base spec produces correct behavior; per FNA bit 0 in Identify Controller, the format may apply to all namespaces. | E63: 1. Identify Controller FNA bit 0 = 1 (format applies to all namespaces simultaneously). 2. Multiple namespaces present. | F63: 1. Issue Format NVM on NSID=1 with valid LBAF. 2. Observe completion. 3. Verify other namespaces also formatted. | G63: Per FNA bit 0 = 1, all namespaces formatted simultaneously. Each namespace shows new FLBAS. | H63: Corner | I63: Exploratory | J63: FNA (Format NVM Attributes) | K63: Sec 4.1.2 (Base spec FNA)

Sheet Summary & Coverage
A1: Format NVM Command - Test Coverage Summary
A3: Specification: | B3: NVM Express NVM Command Set Specification, Revision 1.2 (2025.08.01)
A4: Section: | B4: 4.1.2 Format NVM command (Pages 64-65)
A5: Total Test Cases: | B5: 62
A7: Test Category Distribution
A8: Category | B8: Count | C8: % of Total
A9: Positive | B9: =COUNTIF('Format NVM Test Scenarios'!H:H,"Positive") -> 27 | C9: =B9/$B$5 -> 0.43548387
A10: Negative | B10: =COUNTIF('Format NVM Test Scenarios'!H:H,"Negative") -> 18 | C10: =B10/$B$5 -> 0.29032258
A11: Corner | B11: =COUNTIF('Format NVM Test Scenarios'!H:H,"Corner") -> 17 | C11: =B11/$B$5 -> 0.27419355
A13: Functional Area Coverage (from Section 4.1.2)
A14: Functional Area | B14: # Tests
A15: Combined fields | B15: =COUNTIF('Format NVM Test Scenarios'!J:J,"Combined fields") -> 2
A16: Concurrency | B16: =COUNTIF('Format NVM Test Scenarios'!J:J,"Concurrency") -> 1
A17: Concurrency / state machine | B17: =COUNTIF('Format NVM Test Scenarios'!J:J,"Concurrency / state machine") -> 1
A18: DPS reporting | B18: =COUNTIF('Format NVM Test Scenarios'!J:J,"DPS reporting") -> 2
A19: DPS reporting / PI interaction | B19: =COUNTIF('Format NVM Test Scenarios'!J:J,"DPS reporting / PI interaction") -> 1
A20: Data integrity post-format | B20: =COUNTIF('Format NVM Test Scenarios'!J:J,"Data integrity post-format") -> 1
A21: FLBAS reporting | B21: =COUNTIF('Format NVM Test Scenarios'!J:J,"FLBAS reporting") -> 1
A22: FNA (Format NVM Attributes) | B22: =COUNTIF('Format NVM Test Scenarios'!J:J,"FNA (Format NVM Attributes)") -> 1
A23: Flexible Data Placement | B23: =COUNTIF('Format NVM Test Scenarios'!J:J,"Flexible Data Placement") -> 4
A24: Format Index validation | B24: =COUNTIF('Format NVM Test Scenarios'!J:J,"Format Index validation") -> 5
A25: LBAFEE / extended PI handling | B25: =COUNTIF('Format NVM Test Scenarios'!J:J,"LBAFEE / extended PI handling") -> 10
A26: LBAFEE state transitions | B26: =COUNTIF('Format NVM Test Scenarios'!J:J,"LBAFEE state transitions") -> 1
A27: Metadata Settings (MSET) | B27: =COUNTIF('Format NVM Test Scenarios'!J:J,"Metadata Settings (MSET)") -> 4
A28: NSID handling | B28: =COUNTIF('Format NVM Test Scenarios'!J:J,"NSID handling") -> 3
A29: Namespace size/capacity behavior | B29: =COUNTIF('Format NVM Test Scenarios'!J:J,"Namespace size/capacity behavior") -> 2
A30: Power state interaction | B30: =COUNTIF('Format NVM Test Scenarios'!J:J,"Power state interaction") -> 1
A31: Protection Information (PI) field | B31: =COUNTIF('Format NVM Test Scenarios'!J:J,"Protection Information (PI) field") -> 9
A32: Protection Information Location (PIL) | B32: =COUNTIF('Format NVM Test Scenarios'!J:J,"Protection Information Location (PIL)") -> 5
A33: Reservation interaction | B33: =COUNTIF('Format NVM Test Scenarios'!J:J,"Reservation interaction") -> 1
A34: Reserved field handling | B34: =COUNTIF('Format NVM Test Scenarios'!J:J,"Reserved field handling") -> 2
A35: SQE DPTR handling | B35: =COUNTIF('Format NVM Test Scenarios'!J:J,"SQE DPTR handling") -> 1
A36: STS field consistency | B36: =COUNTIF('Format NVM Test Scenarios'!J:J,"STS field consistency") -> 3
A37: State machine / repeated ops | B37: =COUNTIF('Format NVM Test Scenarios'!J:J,"State machine / repeated ops") -> 1
A40: Testing Techniques Applied
A41: Technique | B41: # Tests
A42: Boundary Value Analysis | B42: =COUNTIF('Format NVM Test Scenarios'!I:I,"Boundary Value Analysis") -> 10
A43: Equivalence Partitioning | B43: =COUNTIF('Format NVM Test Scenarios'!I:I,"Equivalence Partitioning") -> 21
A44: Error Guessing | B44: =COUNTIF('Format NVM Test Scenarios'!I:I,"Error Guessing") -> 11
A45: Exploratory | B45: =COUNTIF('Format NVM Test Scenarios'!I:I,"Exploratory") -> 20
...
